User uploaded file 
/usr/src/app/myapp/views.py changed, reloading.
Watching for file changes with StatReloader
User uploaded file
Error
Warning
/usr/src/app/myapp/urls.py changed, reloading.
Watching for file changes with StatReloader
/usr/src/app/myapp/urls.py changed, reloading.
Watching for file changes with StatReloader
/usr/src/app/myapp/urls.py changed, reloading.
Watching for file changes with StatReloader
/usr/src/app/myapp/urls.py changed, reloading.
Watching for file changes with StatReloader
/usr/src/app/myapp/urls.py changed, reloading.
Watching for file changes with StatReloader
/usr/src/app/myapp/views.py changed, reloading.
Watching for file changes with StatReloader
/usr/src/app/myapp/views.py changed, reloading.
Watching for file changes with StatReloader
/usr/src/app/myapp/views.py changed, reloading.
Watching for file changes with StatReloader
User uploaded file
/usr/src/app/myapp/views.py changed, reloading.
Watching for file changes with StatReloader
/usr/src/app/myapp/views.py changed, reloading.
Watching for file changes with StatReloader
Not Found: /favicon.ico
User uploaded file has been received
Internal Server Error: /uploading_file/
Traceback (most recent call last):
  File "/usr/local/lib/python3.11/site-packages/django/core/handlers/exception.py", line 55, in inner
    response = get_response(request)
               ^^^^^^^^^^^^^^^^^^^^^
  File "/usr/local/lib/python3.11/site-packages/django/core/handlers/base.py", line 204, in _get_response
    self.check_response(response, callback)
  File "/usr/local/lib/python3.11/site-packages/django/core/handlers/base.py", line 332, in check_response
    raise ValueError(
ValueError: The view myapp.views.handling_music_file didn't return an HttpResponse object. It returned None instead.
/usr/src/app/myapp/views.py changed, reloading.
Watching for file changes with StatReloader
/usr/src/app/myapp/views.py changed, reloading.
Watching for file changes with StatReloader
/usr/src/app/myapp/views.py changed, reloading.
Watching for file changes with StatReloader
/usr/src/app/myapp/views.py changed, reloading.
Watching for file changes with StatReloader
User uploaded file has been received
Internal Server Error: /uploading_file/
Traceback (most recent call last):
  File "/usr/local/lib/python3.11/site-packages/django/core/handlers/exception.py", line 55, in inner
    response = get_response(request)
               ^^^^^^^^^^^^^^^^^^^^^
  File "/usr/local/lib/python3.11/site-packages/django/utils/deprecation.py", line 136, in __call__
    response = self.process_response(request, response)
               ^^^^^^^^^^^^^^^^^^^^^^^^^^^^^^^^^^^^^^^^
  File "/usr/local/lib/python3.11/site-packages/django/middleware/clickjacking.py", line 27, in process_response
    if response.get("X-Frame-Options") is not None:
       ^^^^^^^^^^^^
AttributeError: 'str' object has no attribute 'get'
/usr/src/app/myapp/views.py changed, reloading.
Watching for file changes with StatReloader
/usr/src/app/myapp/views.py changed, reloading.
Watching for file changes with StatReloader
User uploaded file has been received
/usr/src/app/myapp/views.py changed, reloading.
Watching for file changes with StatReloader
User uploaded file has been received
/usr/src/app/myapp/views.py changed, reloading.
Watching for file changes with StatReloader
User uploaded file has been received ethereal-vistas-191254.mp3
/usr/src/app/myapp/views.py changed, reloading.
Watching for file changes with StatReloader
Internal Server Error: /uploading_file/
Traceback (most recent call last):
  File "/usr/local/lib/python3.11/site-packages/django/core/handlers/exception.py", line 55, in inner
    response = get_response(request)
               ^^^^^^^^^^^^^^^^^^^^^
  File "/usr/local/lib/python3.11/site-packages/django/core/handlers/base.py", line 197, in _get_response
    response = wrapped_callback(request, *callback_args, **callback_kwargs)
               ^^^^^^^^^^^^^^^^^^^^^^^^^^^^^^^^^^^^^^^^^^^^^^^^^^^^^^^^^^^^
  File "/usr/src/app/myapp/views.py", line 14, in handling_music_file
    logger.info('Unauthenticated user uploaded file %s at %s', request.FILES['audio_file'].name, timezone.now())
                                                                                                 ^^^^^^^^
NameError: name 'timezone' is not defined
/usr/src/app/myapp/views.py changed, reloading.
Watching for file changes with StatReloader
Unauthenticated user uploaded file ethereal-vistas-191254.mp3 at 2024-03-09 13:53:20.754075+00:00
/usr/src/app/myapp/views.py changed, reloading.
Watching for file changes with StatReloader
/usr/src/app/myapp/models.py changed, reloading.
Watching for file changes with StatReloader
/usr/src/app/myapp/models.py changed, reloading.
Watching for file changes with StatReloader
/usr/src/app/myapp/models.py changed, reloading.
Watching for file changes with StatReloader
/usr/src/app/myapp/views.py changed, reloading.
Watching for file changes with StatReloader
/usr/src/app/myapp/views.py changed, reloading.
Watching for file changes with StatReloader
/usr/src/app/myapp/views.py changed, reloading.
Watching for file changes with StatReloader
/usr/src/app/myapp/views.py changed, reloading.
Watching for file changes with StatReloader
/usr/src/app/myapp/views.py changed, reloading.
Watching for file changes with StatReloader
/usr/src/app/myapp/views.py changed, reloading.
Watching for file changes with StatReloader
/usr/src/app/myapp/models.py changed, reloading.
Watching for file changes with StatReloader
/usr/src/app/myapp/models.py changed, reloading.
Watching for file changes with StatReloader
/usr/src/app/myapp/models.py changed, reloading.
Watching for file changes with StatReloader
/usr/src/app/myapp/models.py changed, reloading.
Watching for file changes with StatReloader
/usr/src/app/myapp/views.py changed, reloading.
Watching for file changes with StatReloader
/usr/src/app/myapp/views.py changed, reloading.
Watching for file changes with StatReloader
/usr/src/app/myapp/models.py changed, reloading.
Watching for file changes with StatReloader
/usr/src/app/myapp/models.py changed, reloading.
Watching for file changes with StatReloader
/usr/src/app/myapp/models.py changed, reloading.
Watching for file changes with StatReloader
/usr/src/app/myapp/views.py changed, reloading.
Watching for file changes with StatReloader
Internal Server Error: /uploading_file/
Traceback (most recent call last):
  File "/usr/local/lib/python3.11/site-packages/django/core/handlers/exception.py", line 55, in inner
    response = get_response(request)
               ^^^^^^^^^^^^^^^^^^^^^
  File "/usr/local/lib/python3.11/site-packages/django/core/handlers/base.py", line 197, in _get_response
    response = wrapped_callback(request, *callback_args, **callback_kwargs)
               ^^^^^^^^^^^^^^^^^^^^^^^^^^^^^^^^^^^^^^^^^^^^^^^^^^^^^^^^^^^^
  File "/usr/src/app/myapp/views.py", line 19, in handling_music_file
    log_data = get_log_data(Action.UPLOAD_FILE, 'success', file=request.FILES['audio_file'].name)
               ^^^^^^^^^^^^
NameError: name 'get_log_data' is not defined
/usr/src/app/myapp/views.py changed, reloading.
Watching for file changes with StatReloader
/usr/src/app/myapp/views.py changed, reloading.
Watching for file changes with StatReloader
/usr/src/app/myapp/views.py changed, reloading.
Watching for file changes with StatReloader
/usr/src/app/myapp/models.py changed, reloading.
Watching for file changes with StatReloader
Internal Server Error: /uploading_file/
Traceback (most recent call last):
  File "/usr/local/lib/python3.11/site-packages/django/core/handlers/exception.py", line 55, in inner
    response = get_response(request)
               ^^^^^^^^^^^^^^^^^^^^^
  File "/usr/local/lib/python3.11/site-packages/django/core/handlers/base.py", line 197, in _get_response
    response = wrapped_callback(request, *callback_args, **callback_kwargs)
               ^^^^^^^^^^^^^^^^^^^^^^^^^^^^^^^^^^^^^^^^^^^^^^^^^^^^^^^^^^^^
  File "/usr/src/app/myapp/views.py", line 28, in handling_music_file
    log_data = get_log_data(Action.UPLOAD_FILE, 'success', file=request.FILES['audio_file'].name)
               ^^^^^^^^^^^^^^^^^^^^^^^^^^^^^^^^^^^^^^^^^^^^^^^^^^^^^^^^^^^^^^^^^^^^^^^^^^^^^^^^^^
  File "/usr/src/app/myapp/views.py", line 15, in get_log_data
    log_data.update(additional_fields)
                    ^^^^^^^^^^^^^^^^^
NameError: name 'additional_fields' is not defined
/usr/src/app/myapp/views.py changed, reloading.
Watching for file changes with StatReloader
Internal Server Error: /uploading_file/
Traceback (most recent call last):
  File "/usr/local/lib/python3.11/site-packages/django/db/backends/utils.py", line 134, in debug_sql
    yield
  File "/usr/local/lib/python3.11/site-packages/django/db/backends/utils.py", line 122, in execute
    return super().execute(sql, params)
           ^^^^^^^^^^^^^^^^^^^^^^^^^^^^
  File "/usr/local/lib/python3.11/site-packages/django/db/backends/utils.py", line 79, in execute
    return self._execute_with_wrappers(
           ^^^^^^^^^^^^^^^^^^^^^^^^^^^^
  File "/usr/local/lib/python3.11/site-packages/django/db/backends/utils.py", line 92, in _execute_with_wrappers
    return executor(sql, params, many, context)
           ^^^^^^^^^^^^^^^^^^^^^^^^^^^^^^^^^^^^
  File "/usr/local/lib/python3.11/site-packages/django/db/backends/utils.py", line 105, in _execute
    return self.cursor.execute(sql, params)
           ^^^^^^^^^^^^^^^^^^^^^^^^^^^^^^^^
  File "/usr/local/lib/python3.11/site-packages/psycopg/cursor.py", line 728, in execute
    self._conn.wait(
  File "/usr/local/lib/python3.11/site-packages/psycopg/connection.py", line 969, in wait
    return waiting.wait(gen, self.pgconn.socket, timeout=timeout)
           ^^^^^^^^^^^^^^^^^^^^^^^^^^^^^^^^^^^^^^^^^^^^^^^^^^^^^^
  File "psycopg_binary/_psycopg/waiting.pyx", line 190, in psycopg_binary._psycopg.wait_c
  File "/usr/local/lib/python3.11/site-packages/psycopg/cursor.py", line 210, in _execute_gen
    pgq = self._convert_query(query, params)
          ^^^^^^^^^^^^^^^^^^^^^^^^^^^^^^^^^^
  File "/usr/local/lib/python3.11/site-packages/psycopg/client_cursor.py", line 79, in _convert_query
    pgq.convert(query, params)
  File "/usr/local/lib/python3.11/site-packages/psycopg/_queries.py", line 213, in convert
    self.dump(vars)
  File "/usr/local/lib/python3.11/site-packages/psycopg/_queries.py", line 223, in dump
    self.params = tuple(
                  ^^^^^^
  File "/usr/local/lib/python3.11/site-packages/psycopg/_queries.py", line 224, in <genexpr>
    self._tx.as_literal(p) if p is not None else b"NULL" for p in params
    ^^^^^^^^^^^^^^^^^^^^^^
  File "psycopg_binary/_psycopg/transform.pyx", line 206, in psycopg_binary._psycopg.Transformer.as_literal
  File "psycopg_binary/_psycopg/transform.pyx", line 215, in psycopg_binary._psycopg.Transformer.as_literal
  File "/usr/local/lib/python3.11/site-packages/psycopg/adapt.py", line 57, in quote
    value = self.dump(obj)
            ^^^^^^^^^^^^^^
  File "/usr/local/lib/python3.11/site-packages/psycopg/types/json.py", line 151, in dump
    data = dumps(obj)
           ^^^^^^^^^^
  File "/usr/local/lib/python3.11/json/__init__.py", line 231, in dumps
    return _default_encoder.encode(obj)
           ^^^^^^^^^^^^^^^^^^^^^^^^^^^^
  File "/usr/local/lib/python3.11/json/encoder.py", line 200, in encode
    chunks = self.iterencode(o, _one_shot=True)
             ^^^^^^^^^^^^^^^^^^^^^^^^^^^^^^^^^^
  File "/usr/local/lib/python3.11/json/encoder.py", line 258, in iterencode
    return _iterencode(o, 0)
           ^^^^^^^^^^^^^^^^^
  File "/usr/local/lib/python3.11/json/encoder.py", line 180, in default
    raise TypeError(f'Object of type {o.__class__.__name__} '
TypeError: Object of type Action is not JSON serializable

During handling of the above exception, another exception occurred:

Traceback (most recent call last):
  File "/usr/local/lib/python3.11/site-packages/django/core/handlers/exception.py", line 55, in inner
    response = get_response(request)
               ^^^^^^^^^^^^^^^^^^^^^
  File "/usr/local/lib/python3.11/site-packages/django/core/handlers/base.py", line 197, in _get_response
    response = wrapped_callback(request, *callback_args, **callback_kwargs)
               ^^^^^^^^^^^^^^^^^^^^^^^^^^^^^^^^^^^^^^^^^^^^^^^^^^^^^^^^^^^^
  File "/usr/src/app/myapp/views.py", line 29, in handling_music_file
    create_log(request.user if request.user.is_authenticated else None, log_data)
  File "/usr/src/app/myapp/views.py", line 19, in create_log
    Log.objects.create(user=user, log=log_data)
  File "/usr/local/lib/python3.11/site-packages/django/db/models/manager.py", line 87, in manager_method
    return getattr(self.get_queryset(), name)(*args, **kwargs)
           ^^^^^^^^^^^^^^^^^^^^^^^^^^^^^^^^^^^^^^^^^^^^^^^^^^^
  File "/usr/local/lib/python3.11/site-packages/django/db/models/query.py", line 677, in create
    obj.save(force_insert=True, using=self.db)
  File "/usr/local/lib/python3.11/site-packages/django/db/models/base.py", line 822, in save
    self.save_base(
  File "/usr/local/lib/python3.11/site-packages/django/db/models/base.py", line 909, in save_base
    updated = self._save_table(
              ^^^^^^^^^^^^^^^^^
  File "/usr/local/lib/python3.11/site-packages/django/db/models/base.py", line 1067, in _save_table
    results = self._do_insert(
              ^^^^^^^^^^^^^^^^
  File "/usr/local/lib/python3.11/site-packages/django/db/models/base.py", line 1108, in _do_insert
    return manager._insert(
           ^^^^^^^^^^^^^^^^
  File "/usr/local/lib/python3.11/site-packages/django/db/models/manager.py", line 87, in manager_method
    return getattr(self.get_queryset(), name)(*args, **kwargs)
           ^^^^^^^^^^^^^^^^^^^^^^^^^^^^^^^^^^^^^^^^^^^^^^^^^^^
  File "/usr/local/lib/python3.11/site-packages/django/db/models/query.py", line 1845, in _insert
    return query.get_compiler(using=using).execute_sql(returning_fields)
           ^^^^^^^^^^^^^^^^^^^^^^^^^^^^^^^^^^^^^^^^^^^^^^^^^^^^^^^^^^^^^
  File "/usr/local/lib/python3.11/site-packages/django/db/models/sql/compiler.py", line 1823, in execute_sql
    cursor.execute(sql, params)
  File "/usr/local/lib/python3.11/site-packages/django/db/backends/utils.py", line 121, in execute
    with self.debug_sql(sql, params, use_last_executed_query=True):
  File "/usr/local/lib/python3.11/contextlib.py", line 158, in __exit__
    self.gen.throw(typ, value, traceback)
  File "/usr/local/lib/python3.11/site-packages/django/db/backends/utils.py", line 139, in debug_sql
    sql = self.db.ops.last_executed_query(self.cursor, sql, params)
          ^^^^^^^^^^^^^^^^^^^^^^^^^^^^^^^^^^^^^^^^^^^^^^^^^^^^^^^^^
  File "/usr/local/lib/python3.11/site-packages/django/db/backends/postgresql/operations.py", line 302, in last_executed_query
    return self.compose_sql(sql, params)
           ^^^^^^^^^^^^^^^^^^^^^^^^^^^^^
  File "/usr/local/lib/python3.11/site-packages/django/db/backends/postgresql/operations.py", line 195, in compose_sql
    return mogrify(sql, params, self.connection)
           ^^^^^^^^^^^^^^^^^^^^^^^^^^^^^^^^^^^^^
  File "/usr/local/lib/python3.11/site-packages/django/db/backends/postgresql/psycopg_any.py", line 22, in mogrify
    return ClientCursor(cursor.connection).mogrify(sql, params)
           ^^^^^^^^^^^^^^^^^^^^^^^^^^^^^^^^^^^^^^^^^^^^^^^^^^^^
  File "/usr/local/lib/python3.11/site-packages/psycopg/client_cursor.py", line 40, in mogrify
    pgq = self._convert_query(query, params)
          ^^^^^^^^^^^^^^^^^^^^^^^^^^^^^^^^^^
  File "/usr/local/lib/python3.11/site-packages/psycopg/client_cursor.py", line 79, in _convert_query
    pgq.convert(query, params)
  File "/usr/local/lib/python3.11/site-packages/psycopg/_queries.py", line 213, in convert
    self.dump(vars)
  File "/usr/local/lib/python3.11/site-packages/psycopg/_queries.py", line 223, in dump
    self.params = tuple(
                  ^^^^^^
  File "/usr/local/lib/python3.11/site-packages/psycopg/_queries.py", line 224, in <genexpr>
    self._tx.as_literal(p) if p is not None else b"NULL" for p in params
    ^^^^^^^^^^^^^^^^^^^^^^
  File "psycopg_binary/_psycopg/transform.pyx", line 206, in psycopg_binary._psycopg.Transformer.as_literal
  File "psycopg_binary/_psycopg/transform.pyx", line 215, in psycopg_binary._psycopg.Transformer.as_literal
  File "/usr/local/lib/python3.11/site-packages/psycopg/adapt.py", line 57, in quote
    value = self.dump(obj)
            ^^^^^^^^^^^^^^
  File "/usr/local/lib/python3.11/site-packages/psycopg/types/json.py", line 151, in dump
    data = dumps(obj)
           ^^^^^^^^^^
  File "/usr/local/lib/python3.11/json/__init__.py", line 231, in dumps
    return _default_encoder.encode(obj)
           ^^^^^^^^^^^^^^^^^^^^^^^^^^^^
  File "/usr/local/lib/python3.11/json/encoder.py", line 200, in encode
    chunks = self.iterencode(o, _one_shot=True)
             ^^^^^^^^^^^^^^^^^^^^^^^^^^^^^^^^^^
  File "/usr/local/lib/python3.11/json/encoder.py", line 258, in iterencode
    return _iterencode(o, 0)
           ^^^^^^^^^^^^^^^^^
  File "/usr/local/lib/python3.11/json/encoder.py", line 180, in default
    raise TypeError(f'Object of type {o.__class__.__name__} '
TypeError: Object of type Action is not JSON serializable
/usr/src/app/myapp/views.py changed, reloading.
Watching for file changes with StatReloader
/usr/src/app/myapp/views.py changed, reloading.
Watching for file changes with StatReloader
Internal Server Error: /uploading_file/
Traceback (most recent call last):
  File "/usr/local/lib/python3.11/site-packages/django/db/backends/utils.py", line 105, in _execute
    return self.cursor.execute(sql, params)
           ^^^^^^^^^^^^^^^^^^^^^^^^^^^^^^^^
  File "/usr/local/lib/python3.11/site-packages/psycopg/cursor.py", line 732, in execute
    raise ex.with_traceback(None)
psycopg.errors.UndefinedTable: relation "myapp_log" does not exist
LINE 1: INSERT INTO "myapp_log" ("date", "user_id", "log") VALUES ('...
                    ^

The above exception was the direct cause of the following exception:

Traceback (most recent call last):
  File "/usr/local/lib/python3.11/site-packages/django/core/handlers/exception.py", line 55, in inner
    response = get_response(request)
               ^^^^^^^^^^^^^^^^^^^^^
  File "/usr/local/lib/python3.11/site-packages/django/core/handlers/base.py", line 197, in _get_response
    response = wrapped_callback(request, *callback_args, **callback_kwargs)
               ^^^^^^^^^^^^^^^^^^^^^^^^^^^^^^^^^^^^^^^^^^^^^^^^^^^^^^^^^^^^
  File "/usr/src/app/myapp/views.py", line 29, in handling_music_file
    create_log(request.user if request.user.is_authenticated else None, log_data)
  File "/usr/src/app/myapp/views.py", line 19, in create_log
    Log.objects.create(user=user, log=log_data)
  File "/usr/local/lib/python3.11/site-packages/django/db/models/manager.py", line 87, in manager_method
    return getattr(self.get_queryset(), name)(*args, **kwargs)
           ^^^^^^^^^^^^^^^^^^^^^^^^^^^^^^^^^^^^^^^^^^^^^^^^^^^
  File "/usr/local/lib/python3.11/site-packages/django/db/models/query.py", line 677, in create
    obj.save(force_insert=True, using=self.db)
  File "/usr/local/lib/python3.11/site-packages/django/db/models/base.py", line 822, in save
    self.save_base(
  File "/usr/local/lib/python3.11/site-packages/django/db/models/base.py", line 909, in save_base
    updated = self._save_table(
              ^^^^^^^^^^^^^^^^^
  File "/usr/local/lib/python3.11/site-packages/django/db/models/base.py", line 1067, in _save_table
    results = self._do_insert(
              ^^^^^^^^^^^^^^^^
  File "/usr/local/lib/python3.11/site-packages/django/db/models/base.py", line 1108, in _do_insert
    return manager._insert(
           ^^^^^^^^^^^^^^^^
  File "/usr/local/lib/python3.11/site-packages/django/db/models/manager.py", line 87, in manager_method
    return getattr(self.get_queryset(), name)(*args, **kwargs)
           ^^^^^^^^^^^^^^^^^^^^^^^^^^^^^^^^^^^^^^^^^^^^^^^^^^^
  File "/usr/local/lib/python3.11/site-packages/django/db/models/query.py", line 1845, in _insert
    return query.get_compiler(using=using).execute_sql(returning_fields)
           ^^^^^^^^^^^^^^^^^^^^^^^^^^^^^^^^^^^^^^^^^^^^^^^^^^^^^^^^^^^^^
  File "/usr/local/lib/python3.11/site-packages/django/db/models/sql/compiler.py", line 1823, in execute_sql
    cursor.execute(sql, params)
  File "/usr/local/lib/python3.11/site-packages/django/db/backends/utils.py", line 122, in execute
    return super().execute(sql, params)
           ^^^^^^^^^^^^^^^^^^^^^^^^^^^^
  File "/usr/local/lib/python3.11/site-packages/django/db/backends/utils.py", line 79, in execute
    return self._execute_with_wrappers(
           ^^^^^^^^^^^^^^^^^^^^^^^^^^^^
  File "/usr/local/lib/python3.11/site-packages/django/db/backends/utils.py", line 92, in _execute_with_wrappers
    return executor(sql, params, many, context)
           ^^^^^^^^^^^^^^^^^^^^^^^^^^^^^^^^^^^^
  File "/usr/local/lib/python3.11/site-packages/django/db/backends/utils.py", line 100, in _execute
    with self.db.wrap_database_errors:
  File "/usr/local/lib/python3.11/site-packages/django/db/utils.py", line 91, in __exit__
    raise dj_exc_value.with_traceback(traceback) from exc_value
  File "/usr/local/lib/python3.11/site-packages/django/db/backends/utils.py", line 105, in _execute
    return self.cursor.execute(sql, params)
           ^^^^^^^^^^^^^^^^^^^^^^^^^^^^^^^^
  File "/usr/local/lib/python3.11/site-packages/psycopg/cursor.py", line 732, in execute
    raise ex.with_traceback(None)
django.db.utils.ProgrammingError: relation "myapp_log" does not exist
LINE 1: INSERT INTO "myapp_log" ("date", "user_id", "log") VALUES ('...
                    ^
/usr/src/app/myapp/views.py changed, reloading.
Watching for file changes with StatReloader
/usr/src/app/myapp/views.py changed, reloading.
Watching for file changes with StatReloader
/usr/src/app/myapp/views.py changed, reloading.
Watching for file changes with StatReloader
/usr/src/app/myapp/views.py changed, reloading.
Watching for file changes with StatReloader
