User uploaded file 
/usr/src/app/myapp/views.py changed, reloading.
Watching for file changes with StatReloader
User uploaded file
Error
Warning
/usr/src/app/myapp/urls.py changed, reloading.
Watching for file changes with StatReloader
/usr/src/app/myapp/urls.py changed, reloading.
Watching for file changes with StatReloader
/usr/src/app/myapp/urls.py changed, reloading.
Watching for file changes with StatReloader
/usr/src/app/myapp/urls.py changed, reloading.
Watching for file changes with StatReloader
/usr/src/app/myapp/urls.py changed, reloading.
Watching for file changes with StatReloader
/usr/src/app/myapp/views.py changed, reloading.
Watching for file changes with StatReloader
/usr/src/app/myapp/views.py changed, reloading.
Watching for file changes with StatReloader
/usr/src/app/myapp/views.py changed, reloading.
Watching for file changes with StatReloader
User uploaded file
/usr/src/app/myapp/views.py changed, reloading.
Watching for file changes with StatReloader
/usr/src/app/myapp/views.py changed, reloading.
Watching for file changes with StatReloader
Not Found: /favicon.ico
User uploaded file has been received
Internal Server Error: /uploading_file/
Traceback (most recent call last):
  File "/usr/local/lib/python3.11/site-packages/django/core/handlers/exception.py", line 55, in inner
    response = get_response(request)
               ^^^^^^^^^^^^^^^^^^^^^
  File "/usr/local/lib/python3.11/site-packages/django/core/handlers/base.py", line 204, in _get_response
    self.check_response(response, callback)
  File "/usr/local/lib/python3.11/site-packages/django/core/handlers/base.py", line 332, in check_response
    raise ValueError(
ValueError: The view myapp.views.handling_music_file didn't return an HttpResponse object. It returned None instead.
/usr/src/app/myapp/views.py changed, reloading.
Watching for file changes with StatReloader
/usr/src/app/myapp/views.py changed, reloading.
Watching for file changes with StatReloader
/usr/src/app/myapp/views.py changed, reloading.
Watching for file changes with StatReloader
/usr/src/app/myapp/views.py changed, reloading.
Watching for file changes with StatReloader
User uploaded file has been received
Internal Server Error: /uploading_file/
Traceback (most recent call last):
  File "/usr/local/lib/python3.11/site-packages/django/core/handlers/exception.py", line 55, in inner
    response = get_response(request)
               ^^^^^^^^^^^^^^^^^^^^^
  File "/usr/local/lib/python3.11/site-packages/django/utils/deprecation.py", line 136, in __call__
    response = self.process_response(request, response)
               ^^^^^^^^^^^^^^^^^^^^^^^^^^^^^^^^^^^^^^^^
  File "/usr/local/lib/python3.11/site-packages/django/middleware/clickjacking.py", line 27, in process_response
    if response.get("X-Frame-Options") is not None:
       ^^^^^^^^^^^^
AttributeError: 'str' object has no attribute 'get'
/usr/src/app/myapp/views.py changed, reloading.
Watching for file changes with StatReloader
/usr/src/app/myapp/views.py changed, reloading.
Watching for file changes with StatReloader
User uploaded file has been received
/usr/src/app/myapp/views.py changed, reloading.
Watching for file changes with StatReloader
User uploaded file has been received
/usr/src/app/myapp/views.py changed, reloading.
Watching for file changes with StatReloader
User uploaded file has been received ethereal-vistas-191254.mp3
/usr/src/app/myapp/views.py changed, reloading.
Watching for file changes with StatReloader
Internal Server Error: /uploading_file/
Traceback (most recent call last):
  File "/usr/local/lib/python3.11/site-packages/django/core/handlers/exception.py", line 55, in inner
    response = get_response(request)
               ^^^^^^^^^^^^^^^^^^^^^
  File "/usr/local/lib/python3.11/site-packages/django/core/handlers/base.py", line 197, in _get_response
    response = wrapped_callback(request, *callback_args, **callback_kwargs)
               ^^^^^^^^^^^^^^^^^^^^^^^^^^^^^^^^^^^^^^^^^^^^^^^^^^^^^^^^^^^^
  File "/usr/src/app/myapp/views.py", line 14, in handling_music_file
    logger.info('Unauthenticated user uploaded file %s at %s', request.FILES['audio_file'].name, timezone.now())
                                                                                                 ^^^^^^^^
NameError: name 'timezone' is not defined
/usr/src/app/myapp/views.py changed, reloading.
Watching for file changes with StatReloader
Unauthenticated user uploaded file ethereal-vistas-191254.mp3 at 2024-03-09 13:53:20.754075+00:00
/usr/src/app/myapp/views.py changed, reloading.
Watching for file changes with StatReloader
/usr/src/app/myapp/models.py changed, reloading.
Watching for file changes with StatReloader
/usr/src/app/myapp/models.py changed, reloading.
Watching for file changes with StatReloader
/usr/src/app/myapp/models.py changed, reloading.
Watching for file changes with StatReloader
/usr/src/app/myapp/views.py changed, reloading.
Watching for file changes with StatReloader
/usr/src/app/myapp/views.py changed, reloading.
Watching for file changes with StatReloader
/usr/src/app/myapp/views.py changed, reloading.
Watching for file changes with StatReloader
/usr/src/app/myapp/views.py changed, reloading.
Watching for file changes with StatReloader
/usr/src/app/myapp/views.py changed, reloading.
Watching for file changes with StatReloader
/usr/src/app/myapp/views.py changed, reloading.
Watching for file changes with StatReloader
/usr/src/app/myapp/models.py changed, reloading.
Watching for file changes with StatReloader
/usr/src/app/myapp/models.py changed, reloading.
Watching for file changes with StatReloader
/usr/src/app/myapp/models.py changed, reloading.
Watching for file changes with StatReloader
/usr/src/app/myapp/models.py changed, reloading.
Watching for file changes with StatReloader
/usr/src/app/myapp/views.py changed, reloading.
Watching for file changes with StatReloader
/usr/src/app/myapp/views.py changed, reloading.
Watching for file changes with StatReloader
/usr/src/app/myapp/models.py changed, reloading.
Watching for file changes with StatReloader
/usr/src/app/myapp/models.py changed, reloading.
Watching for file changes with StatReloader
/usr/src/app/myapp/models.py changed, reloading.
Watching for file changes with StatReloader
/usr/src/app/myapp/views.py changed, reloading.
Watching for file changes with StatReloader
Internal Server Error: /uploading_file/
Traceback (most recent call last):
  File "/usr/local/lib/python3.11/site-packages/django/core/handlers/exception.py", line 55, in inner
    response = get_response(request)
               ^^^^^^^^^^^^^^^^^^^^^
  File "/usr/local/lib/python3.11/site-packages/django/core/handlers/base.py", line 197, in _get_response
    response = wrapped_callback(request, *callback_args, **callback_kwargs)
               ^^^^^^^^^^^^^^^^^^^^^^^^^^^^^^^^^^^^^^^^^^^^^^^^^^^^^^^^^^^^
  File "/usr/src/app/myapp/views.py", line 19, in handling_music_file
    log_data = get_log_data(Action.UPLOAD_FILE, 'success', file=request.FILES['audio_file'].name)
               ^^^^^^^^^^^^
NameError: name 'get_log_data' is not defined
/usr/src/app/myapp/views.py changed, reloading.
Watching for file changes with StatReloader
/usr/src/app/myapp/views.py changed, reloading.
Watching for file changes with StatReloader
/usr/src/app/myapp/views.py changed, reloading.
Watching for file changes with StatReloader
/usr/src/app/myapp/models.py changed, reloading.
Watching for file changes with StatReloader
Internal Server Error: /uploading_file/
Traceback (most recent call last):
  File "/usr/local/lib/python3.11/site-packages/django/core/handlers/exception.py", line 55, in inner
    response = get_response(request)
               ^^^^^^^^^^^^^^^^^^^^^
  File "/usr/local/lib/python3.11/site-packages/django/core/handlers/base.py", line 197, in _get_response
    response = wrapped_callback(request, *callback_args, **callback_kwargs)
               ^^^^^^^^^^^^^^^^^^^^^^^^^^^^^^^^^^^^^^^^^^^^^^^^^^^^^^^^^^^^
  File "/usr/src/app/myapp/views.py", line 28, in handling_music_file
    log_data = get_log_data(Action.UPLOAD_FILE, 'success', file=request.FILES['audio_file'].name)
               ^^^^^^^^^^^^^^^^^^^^^^^^^^^^^^^^^^^^^^^^^^^^^^^^^^^^^^^^^^^^^^^^^^^^^^^^^^^^^^^^^^
  File "/usr/src/app/myapp/views.py", line 15, in get_log_data
    log_data.update(additional_fields)
                    ^^^^^^^^^^^^^^^^^
NameError: name 'additional_fields' is not defined
/usr/src/app/myapp/views.py changed, reloading.
Watching for file changes with StatReloader
Internal Server Error: /uploading_file/
Traceback (most recent call last):
  File "/usr/local/lib/python3.11/site-packages/django/db/backends/utils.py", line 134, in debug_sql
    yield
  File "/usr/local/lib/python3.11/site-packages/django/db/backends/utils.py", line 122, in execute
    return super().execute(sql, params)
           ^^^^^^^^^^^^^^^^^^^^^^^^^^^^
  File "/usr/local/lib/python3.11/site-packages/django/db/backends/utils.py", line 79, in execute
    return self._execute_with_wrappers(
           ^^^^^^^^^^^^^^^^^^^^^^^^^^^^
  File "/usr/local/lib/python3.11/site-packages/django/db/backends/utils.py", line 92, in _execute_with_wrappers
    return executor(sql, params, many, context)
           ^^^^^^^^^^^^^^^^^^^^^^^^^^^^^^^^^^^^
  File "/usr/local/lib/python3.11/site-packages/django/db/backends/utils.py", line 105, in _execute
    return self.cursor.execute(sql, params)
           ^^^^^^^^^^^^^^^^^^^^^^^^^^^^^^^^
  File "/usr/local/lib/python3.11/site-packages/psycopg/cursor.py", line 728, in execute
    self._conn.wait(
  File "/usr/local/lib/python3.11/site-packages/psycopg/connection.py", line 969, in wait
    return waiting.wait(gen, self.pgconn.socket, timeout=timeout)
           ^^^^^^^^^^^^^^^^^^^^^^^^^^^^^^^^^^^^^^^^^^^^^^^^^^^^^^
  File "psycopg_binary/_psycopg/waiting.pyx", line 190, in psycopg_binary._psycopg.wait_c
  File "/usr/local/lib/python3.11/site-packages/psycopg/cursor.py", line 210, in _execute_gen
    pgq = self._convert_query(query, params)
          ^^^^^^^^^^^^^^^^^^^^^^^^^^^^^^^^^^
  File "/usr/local/lib/python3.11/site-packages/psycopg/client_cursor.py", line 79, in _convert_query
    pgq.convert(query, params)
  File "/usr/local/lib/python3.11/site-packages/psycopg/_queries.py", line 213, in convert
    self.dump(vars)
  File "/usr/local/lib/python3.11/site-packages/psycopg/_queries.py", line 223, in dump
    self.params = tuple(
                  ^^^^^^
  File "/usr/local/lib/python3.11/site-packages/psycopg/_queries.py", line 224, in <genexpr>
    self._tx.as_literal(p) if p is not None else b"NULL" for p in params
    ^^^^^^^^^^^^^^^^^^^^^^
  File "psycopg_binary/_psycopg/transform.pyx", line 206, in psycopg_binary._psycopg.Transformer.as_literal
  File "psycopg_binary/_psycopg/transform.pyx", line 215, in psycopg_binary._psycopg.Transformer.as_literal
  File "/usr/local/lib/python3.11/site-packages/psycopg/adapt.py", line 57, in quote
    value = self.dump(obj)
            ^^^^^^^^^^^^^^
  File "/usr/local/lib/python3.11/site-packages/psycopg/types/json.py", line 151, in dump
    data = dumps(obj)
           ^^^^^^^^^^
  File "/usr/local/lib/python3.11/json/__init__.py", line 231, in dumps
    return _default_encoder.encode(obj)
           ^^^^^^^^^^^^^^^^^^^^^^^^^^^^
  File "/usr/local/lib/python3.11/json/encoder.py", line 200, in encode
    chunks = self.iterencode(o, _one_shot=True)
             ^^^^^^^^^^^^^^^^^^^^^^^^^^^^^^^^^^
  File "/usr/local/lib/python3.11/json/encoder.py", line 258, in iterencode
    return _iterencode(o, 0)
           ^^^^^^^^^^^^^^^^^
  File "/usr/local/lib/python3.11/json/encoder.py", line 180, in default
    raise TypeError(f'Object of type {o.__class__.__name__} '
TypeError: Object of type Action is not JSON serializable

During handling of the above exception, another exception occurred:

Traceback (most recent call last):
  File "/usr/local/lib/python3.11/site-packages/django/core/handlers/exception.py", line 55, in inner
    response = get_response(request)
               ^^^^^^^^^^^^^^^^^^^^^
  File "/usr/local/lib/python3.11/site-packages/django/core/handlers/base.py", line 197, in _get_response
    response = wrapped_callback(request, *callback_args, **callback_kwargs)
               ^^^^^^^^^^^^^^^^^^^^^^^^^^^^^^^^^^^^^^^^^^^^^^^^^^^^^^^^^^^^
  File "/usr/src/app/myapp/views.py", line 29, in handling_music_file
    create_log(request.user if request.user.is_authenticated else None, log_data)
  File "/usr/src/app/myapp/views.py", line 19, in create_log
    Log.objects.create(user=user, log=log_data)
  File "/usr/local/lib/python3.11/site-packages/django/db/models/manager.py", line 87, in manager_method
    return getattr(self.get_queryset(), name)(*args, **kwargs)
           ^^^^^^^^^^^^^^^^^^^^^^^^^^^^^^^^^^^^^^^^^^^^^^^^^^^
  File "/usr/local/lib/python3.11/site-packages/django/db/models/query.py", line 677, in create
    obj.save(force_insert=True, using=self.db)
  File "/usr/local/lib/python3.11/site-packages/django/db/models/base.py", line 822, in save
    self.save_base(
  File "/usr/local/lib/python3.11/site-packages/django/db/models/base.py", line 909, in save_base
    updated = self._save_table(
              ^^^^^^^^^^^^^^^^^
  File "/usr/local/lib/python3.11/site-packages/django/db/models/base.py", line 1067, in _save_table
    results = self._do_insert(
              ^^^^^^^^^^^^^^^^
  File "/usr/local/lib/python3.11/site-packages/django/db/models/base.py", line 1108, in _do_insert
    return manager._insert(
           ^^^^^^^^^^^^^^^^
  File "/usr/local/lib/python3.11/site-packages/django/db/models/manager.py", line 87, in manager_method
    return getattr(self.get_queryset(), name)(*args, **kwargs)
           ^^^^^^^^^^^^^^^^^^^^^^^^^^^^^^^^^^^^^^^^^^^^^^^^^^^
  File "/usr/local/lib/python3.11/site-packages/django/db/models/query.py", line 1845, in _insert
    return query.get_compiler(using=using).execute_sql(returning_fields)
           ^^^^^^^^^^^^^^^^^^^^^^^^^^^^^^^^^^^^^^^^^^^^^^^^^^^^^^^^^^^^^
  File "/usr/local/lib/python3.11/site-packages/django/db/models/sql/compiler.py", line 1823, in execute_sql
    cursor.execute(sql, params)
  File "/usr/local/lib/python3.11/site-packages/django/db/backends/utils.py", line 121, in execute
    with self.debug_sql(sql, params, use_last_executed_query=True):
  File "/usr/local/lib/python3.11/contextlib.py", line 158, in __exit__
    self.gen.throw(typ, value, traceback)
  File "/usr/local/lib/python3.11/site-packages/django/db/backends/utils.py", line 139, in debug_sql
    sql = self.db.ops.last_executed_query(self.cursor, sql, params)
          ^^^^^^^^^^^^^^^^^^^^^^^^^^^^^^^^^^^^^^^^^^^^^^^^^^^^^^^^^
  File "/usr/local/lib/python3.11/site-packages/django/db/backends/postgresql/operations.py", line 302, in last_executed_query
    return self.compose_sql(sql, params)
           ^^^^^^^^^^^^^^^^^^^^^^^^^^^^^
  File "/usr/local/lib/python3.11/site-packages/django/db/backends/postgresql/operations.py", line 195, in compose_sql
    return mogrify(sql, params, self.connection)
           ^^^^^^^^^^^^^^^^^^^^^^^^^^^^^^^^^^^^^
  File "/usr/local/lib/python3.11/site-packages/django/db/backends/postgresql/psycopg_any.py", line 22, in mogrify
    return ClientCursor(cursor.connection).mogrify(sql, params)
           ^^^^^^^^^^^^^^^^^^^^^^^^^^^^^^^^^^^^^^^^^^^^^^^^^^^^
  File "/usr/local/lib/python3.11/site-packages/psycopg/client_cursor.py", line 40, in mogrify
    pgq = self._convert_query(query, params)
          ^^^^^^^^^^^^^^^^^^^^^^^^^^^^^^^^^^
  File "/usr/local/lib/python3.11/site-packages/psycopg/client_cursor.py", line 79, in _convert_query
    pgq.convert(query, params)
  File "/usr/local/lib/python3.11/site-packages/psycopg/_queries.py", line 213, in convert
    self.dump(vars)
  File "/usr/local/lib/python3.11/site-packages/psycopg/_queries.py", line 223, in dump
    self.params = tuple(
                  ^^^^^^
  File "/usr/local/lib/python3.11/site-packages/psycopg/_queries.py", line 224, in <genexpr>
    self._tx.as_literal(p) if p is not None else b"NULL" for p in params
    ^^^^^^^^^^^^^^^^^^^^^^
  File "psycopg_binary/_psycopg/transform.pyx", line 206, in psycopg_binary._psycopg.Transformer.as_literal
  File "psycopg_binary/_psycopg/transform.pyx", line 215, in psycopg_binary._psycopg.Transformer.as_literal
  File "/usr/local/lib/python3.11/site-packages/psycopg/adapt.py", line 57, in quote
    value = self.dump(obj)
            ^^^^^^^^^^^^^^
  File "/usr/local/lib/python3.11/site-packages/psycopg/types/json.py", line 151, in dump
    data = dumps(obj)
           ^^^^^^^^^^
  File "/usr/local/lib/python3.11/json/__init__.py", line 231, in dumps
    return _default_encoder.encode(obj)
           ^^^^^^^^^^^^^^^^^^^^^^^^^^^^
  File "/usr/local/lib/python3.11/json/encoder.py", line 200, in encode
    chunks = self.iterencode(o, _one_shot=True)
             ^^^^^^^^^^^^^^^^^^^^^^^^^^^^^^^^^^
  File "/usr/local/lib/python3.11/json/encoder.py", line 258, in iterencode
    return _iterencode(o, 0)
           ^^^^^^^^^^^^^^^^^
  File "/usr/local/lib/python3.11/json/encoder.py", line 180, in default
    raise TypeError(f'Object of type {o.__class__.__name__} '
TypeError: Object of type Action is not JSON serializable
/usr/src/app/myapp/views.py changed, reloading.
Watching for file changes with StatReloader
/usr/src/app/myapp/views.py changed, reloading.
Watching for file changes with StatReloader
Internal Server Error: /uploading_file/
Traceback (most recent call last):
  File "/usr/local/lib/python3.11/site-packages/django/db/backends/utils.py", line 105, in _execute
    return self.cursor.execute(sql, params)
           ^^^^^^^^^^^^^^^^^^^^^^^^^^^^^^^^
  File "/usr/local/lib/python3.11/site-packages/psycopg/cursor.py", line 732, in execute
    raise ex.with_traceback(None)
psycopg.errors.UndefinedTable: relation "myapp_log" does not exist
LINE 1: INSERT INTO "myapp_log" ("date", "user_id", "log") VALUES ('...
                    ^

The above exception was the direct cause of the following exception:

Traceback (most recent call last):
  File "/usr/local/lib/python3.11/site-packages/django/core/handlers/exception.py", line 55, in inner
    response = get_response(request)
               ^^^^^^^^^^^^^^^^^^^^^
  File "/usr/local/lib/python3.11/site-packages/django/core/handlers/base.py", line 197, in _get_response
    response = wrapped_callback(request, *callback_args, **callback_kwargs)
               ^^^^^^^^^^^^^^^^^^^^^^^^^^^^^^^^^^^^^^^^^^^^^^^^^^^^^^^^^^^^
  File "/usr/src/app/myapp/views.py", line 29, in handling_music_file
    create_log(request.user if request.user.is_authenticated else None, log_data)
  File "/usr/src/app/myapp/views.py", line 19, in create_log
    Log.objects.create(user=user, log=log_data)
  File "/usr/local/lib/python3.11/site-packages/django/db/models/manager.py", line 87, in manager_method
    return getattr(self.get_queryset(), name)(*args, **kwargs)
           ^^^^^^^^^^^^^^^^^^^^^^^^^^^^^^^^^^^^^^^^^^^^^^^^^^^
  File "/usr/local/lib/python3.11/site-packages/django/db/models/query.py", line 677, in create
    obj.save(force_insert=True, using=self.db)
  File "/usr/local/lib/python3.11/site-packages/django/db/models/base.py", line 822, in save
    self.save_base(
  File "/usr/local/lib/python3.11/site-packages/django/db/models/base.py", line 909, in save_base
    updated = self._save_table(
              ^^^^^^^^^^^^^^^^^
  File "/usr/local/lib/python3.11/site-packages/django/db/models/base.py", line 1067, in _save_table
    results = self._do_insert(
              ^^^^^^^^^^^^^^^^
  File "/usr/local/lib/python3.11/site-packages/django/db/models/base.py", line 1108, in _do_insert
    return manager._insert(
           ^^^^^^^^^^^^^^^^
  File "/usr/local/lib/python3.11/site-packages/django/db/models/manager.py", line 87, in manager_method
    return getattr(self.get_queryset(), name)(*args, **kwargs)
           ^^^^^^^^^^^^^^^^^^^^^^^^^^^^^^^^^^^^^^^^^^^^^^^^^^^
  File "/usr/local/lib/python3.11/site-packages/django/db/models/query.py", line 1845, in _insert
    return query.get_compiler(using=using).execute_sql(returning_fields)
           ^^^^^^^^^^^^^^^^^^^^^^^^^^^^^^^^^^^^^^^^^^^^^^^^^^^^^^^^^^^^^
  File "/usr/local/lib/python3.11/site-packages/django/db/models/sql/compiler.py", line 1823, in execute_sql
    cursor.execute(sql, params)
  File "/usr/local/lib/python3.11/site-packages/django/db/backends/utils.py", line 122, in execute
    return super().execute(sql, params)
           ^^^^^^^^^^^^^^^^^^^^^^^^^^^^
  File "/usr/local/lib/python3.11/site-packages/django/db/backends/utils.py", line 79, in execute
    return self._execute_with_wrappers(
           ^^^^^^^^^^^^^^^^^^^^^^^^^^^^
  File "/usr/local/lib/python3.11/site-packages/django/db/backends/utils.py", line 92, in _execute_with_wrappers
    return executor(sql, params, many, context)
           ^^^^^^^^^^^^^^^^^^^^^^^^^^^^^^^^^^^^
  File "/usr/local/lib/python3.11/site-packages/django/db/backends/utils.py", line 100, in _execute
    with self.db.wrap_database_errors:
  File "/usr/local/lib/python3.11/site-packages/django/db/utils.py", line 91, in __exit__
    raise dj_exc_value.with_traceback(traceback) from exc_value
  File "/usr/local/lib/python3.11/site-packages/django/db/backends/utils.py", line 105, in _execute
    return self.cursor.execute(sql, params)
           ^^^^^^^^^^^^^^^^^^^^^^^^^^^^^^^^
  File "/usr/local/lib/python3.11/site-packages/psycopg/cursor.py", line 732, in execute
    raise ex.with_traceback(None)
django.db.utils.ProgrammingError: relation "myapp_log" does not exist
LINE 1: INSERT INTO "myapp_log" ("date", "user_id", "log") VALUES ('...
                    ^
/usr/src/app/myapp/views.py changed, reloading.
Watching for file changes with StatReloader
/usr/src/app/myapp/views.py changed, reloading.
Watching for file changes with StatReloader
/usr/src/app/myapp/views.py changed, reloading.
Watching for file changes with StatReloader
/usr/src/app/myapp/views.py changed, reloading.
Watching for file changes with StatReloader
Watching for file changes with StatReloader
Watching for file changes with StatReloader
/usr/src/app/myapp/views.py changed, reloading.
Watching for file changes with StatReloader
/usr/src/app/myapp/views.py changed, reloading.
Watching for file changes with StatReloader
/usr/src/app/myapp/views.py changed, reloading.
Watching for file changes with StatReloader
/usr/src/app/myapp/views.py changed, reloading.
Watching for file changes with StatReloader
/usr/src/app/myapp/views.py changed, reloading.
Watching for file changes with StatReloader
/usr/src/app/myapp/views.py changed, reloading.
Watching for file changes with StatReloader
Watching for file changes with StatReloader
Watching for file changes with StatReloader
/usr/src/app/myapp/views.py changed, reloading.
Watching for file changes with StatReloader
/usr/src/app/myapp/views.py changed, reloading.
Watching for file changes with StatReloader
/usr/src/app/myapp/views.py changed, reloading.
Watching for file changes with StatReloader
/usr/src/app/myapp/views.py changed, reloading.
Watching for file changes with StatReloader
Watching for file changes with StatReloader
/usr/src/app/myapp/forms.py changed, reloading.
Watching for file changes with StatReloader
/usr/src/app/myapp/views.py changed, reloading.
Watching for file changes with StatReloader
/usr/src/app/myapp/forms.py changed, reloading.
Watching for file changes with StatReloader
/usr/src/app/myapp/forms.py changed, reloading.
Watching for file changes with StatReloader
/usr/src/app/myapp/forms.py changed, reloading.
Watching for file changes with StatReloader
/usr/src/app/myapp/forms.py changed, reloading.
Watching for file changes with StatReloader
Watching for file changes with StatReloader
/usr/src/app/myapp/urls.py changed, reloading.
Watching for file changes with StatReloader
/usr/src/app/myapp/urls.py changed, reloading.
Watching for file changes with StatReloader
Watching for file changes with StatReloader
/usr/src/app/myapp/urls.py changed, reloading.
Watching for file changes with StatReloader
/usr/src/app/myapp/views.py changed, reloading.
Watching for file changes with StatReloader
/usr/src/app/myapp/views.py changed, reloading.
Watching for file changes with StatReloader
/usr/src/app/myapp/views.py changed, reloading.
Watching for file changes with StatReloader
Watching for file changes with StatReloader
Watching for file changes with StatReloader
Watching for file changes with StatReloader
Not Found: /favicon.ico
/usr/src/app/myapp/urls.py changed, reloading.
Watching for file changes with StatReloader
/usr/src/app/myapp/views.py changed, reloading.
Watching for file changes with StatReloader
/usr/src/app/myapp/views.py changed, reloading.
Watching for file changes with StatReloader
/usr/src/app/myapp/urls.py changed, reloading.
Watching for file changes with StatReloader
/usr/src/app/myapp/urls.py changed, reloading.
Watching for file changes with StatReloader
/usr/src/app/myapp/urls.py changed, reloading.
Watching for file changes with StatReloader
Internal Server Error: /admin_table/
Traceback (most recent call last):
  File "/usr/local/lib/python3.11/site-packages/django/core/handlers/exception.py", line 55, in inner
    response = get_response(request)
               ^^^^^^^^^^^^^^^^^^^^^
  File "/usr/local/lib/python3.11/site-packages/django/core/handlers/base.py", line 204, in _get_response
    self.check_response(response, callback)
  File "/usr/local/lib/python3.11/site-packages/django/core/handlers/base.py", line 332, in check_response
    raise ValueError(
ValueError: The view myapp.views.admin_table didn't return an HttpResponse object. It returned None instead.
/usr/src/app/myapp/views.py changed, reloading.
Watching for file changes with StatReloader
Internal Server Error: /admin_table/
Traceback (most recent call last):
  File "/usr/local/lib/python3.11/site-packages/django/core/handlers/exception.py", line 55, in inner
    response = get_response(request)
               ^^^^^^^^^^^^^^^^^^^^^
  File "/usr/local/lib/python3.11/site-packages/django/core/handlers/base.py", line 197, in _get_response
    response = wrapped_callback(request, *callback_args, **callback_kwargs)
               ^^^^^^^^^^^^^^^^^^^^^^^^^^^^^^^^^^^^^^^^^^^^^^^^^^^^^^^^^^^^
  File "/usr/src/app/myapp/views.py", line 54, in admin_table
    data = [dict(row) for row in rows]
           ^^^^^^^^^^^^^^^^^^^^^^^^^^^
  File "/usr/src/app/myapp/views.py", line 54, in <listcomp>
    data = [dict(row) for row in rows]
            ^^^^^^^^^
TypeError: cannot convert dictionary update sequence element #0 to a sequence
Internal Server Error: /admin_table/
Traceback (most recent call last):
  File "/usr/local/lib/python3.11/site-packages/django/core/handlers/exception.py", line 55, in inner
    response = get_response(request)
               ^^^^^^^^^^^^^^^^^^^^^
  File "/usr/local/lib/python3.11/site-packages/django/core/handlers/base.py", line 197, in _get_response
    response = wrapped_callback(request, *callback_args, **callback_kwargs)
               ^^^^^^^^^^^^^^^^^^^^^^^^^^^^^^^^^^^^^^^^^^^^^^^^^^^^^^^^^^^^
  File "/usr/src/app/myapp/views.py", line 54, in admin_table
    data = [dict(row) for row in rows]
           ^^^^^^^^^^^^^^^^^^^^^^^^^^^
  File "/usr/src/app/myapp/views.py", line 54, in <listcomp>
    data = [dict(row) for row in rows]
            ^^^^^^^^^
TypeError: cannot convert dictionary update sequence element #0 to a sequence
/usr/src/app/myapp/views.py changed, reloading.
Watching for file changes with StatReloader
/usr/src/app/myapp/views.py changed, reloading.
Watching for file changes with StatReloader
/usr/src/app/myapp/views.py changed, reloading.
Watching for file changes with StatReloader
/usr/src/app/myapp/views.py changed, reloading.
Watching for file changes with StatReloader
/usr/src/app/myapp/views.py changed, reloading.
Watching for file changes with StatReloader
/usr/src/app/myapp/views.py changed, reloading.
Watching for file changes with StatReloader
/usr/src/app/myapp/views.py changed, reloading.
Watching for file changes with StatReloader
/usr/src/app/myapp/views.py changed, reloading.
Watching for file changes with StatReloader
/usr/src/app/myapp/views.py changed, reloading.
Watching for file changes with StatReloader
/usr/src/app/myapp/views.py changed, reloading.
Watching for file changes with StatReloader
/usr/src/app/myapp/views.py changed, reloading.
Watching for file changes with StatReloader
Internal Server Error: /user/
Traceback (most recent call last):
  File "/usr/local/lib/python3.11/site-packages/django/core/handlers/exception.py", line 55, in inner
    response = get_response(request)
               ^^^^^^^^^^^^^^^^^^^^^
  File "/usr/local/lib/python3.11/site-packages/django/core/handlers/base.py", line 197, in _get_response
    response = wrapped_callback(request, *callback_args, **callback_kwargs)
               ^^^^^^^^^^^^^^^^^^^^^^^^^^^^^^^^^^^^^^^^^^^^^^^^^^^^^^^^^^^^
  File "/usr/src/app/myapp/views.py", line 76, in users
    admin_table = admin_table()
                  ^^^^^^^^^^^
UnboundLocalError: cannot access local variable 'admin_table' where it is not associated with a value
/usr/src/app/myapp/views.py changed, reloading.
Watching for file changes with StatReloader
/usr/src/app/myapp/views.py changed, reloading.
Watching for file changes with StatReloader
Internal Server Error: /user/
Traceback (most recent call last):
  File "/usr/local/lib/python3.11/site-packages/django/core/handlers/exception.py", line 55, in inner
    response = get_response(request)
               ^^^^^^^^^^^^^^^^^^^^^
  File "/usr/local/lib/python3.11/site-packages/django/core/handlers/base.py", line 197, in _get_response
    response = wrapped_callback(request, *callback_args, **callback_kwargs)
               ^^^^^^^^^^^^^^^^^^^^^^^^^^^^^^^^^^^^^^^^^^^^^^^^^^^^^^^^^^^^
  File "/usr/src/app/myapp/views.py", line 82, in users
    return render(request, 'user_page.html', context)
           ^^^^^^^^^^^^^^^^^^^^^^^^^^^^^^^^^^^^^^^^^^
  File "/usr/local/lib/python3.11/site-packages/django/shortcuts.py", line 24, in render
    content = loader.render_to_string(template_name, context, request, using=using)
              ^^^^^^^^^^^^^^^^^^^^^^^^^^^^^^^^^^^^^^^^^^^^^^^^^^^^^^^^^^^^^^^^^^^^^
  File "/usr/local/lib/python3.11/site-packages/django/template/loader.py", line 61, in render_to_string
    template = get_template(template_name, using=using)
               ^^^^^^^^^^^^^^^^^^^^^^^^^^^^^^^^^^^^^^^^
  File "/usr/local/lib/python3.11/site-packages/django/template/loader.py", line 15, in get_template
    return engine.get_template(template_name)
           ^^^^^^^^^^^^^^^^^^^^^^^^^^^^^^^^^^
  File "/usr/local/lib/python3.11/site-packages/django/template/backends/django.py", line 33, in get_template
    return Template(self.engine.get_template(template_name), self)
                    ^^^^^^^^^^^^^^^^^^^^^^^^^^^^^^^^^^^^^^^
  File "/usr/local/lib/python3.11/site-packages/django/template/engine.py", line 175, in get_template
    template, origin = self.find_template(template_name)
                       ^^^^^^^^^^^^^^^^^^^^^^^^^^^^^^^^^
  File "/usr/local/lib/python3.11/site-packages/django/template/engine.py", line 157, in find_template
    template = loader.get_template(name, skip=skip)
               ^^^^^^^^^^^^^^^^^^^^^^^^^^^^^^^^^^^^
  File "/usr/local/lib/python3.11/site-packages/django/template/loaders/cached.py", line 57, in get_template
    template = super().get_template(template_name, skip)
               ^^^^^^^^^^^^^^^^^^^^^^^^^^^^^^^^^^^^^^^^^
  File "/usr/local/lib/python3.11/site-packages/django/template/loaders/base.py", line 28, in get_template
    return Template(
           ^^^^^^^^^
  File "/usr/local/lib/python3.11/site-packages/django/template/base.py", line 154, in __init__
    self.nodelist = self.compile_nodelist()
                    ^^^^^^^^^^^^^^^^^^^^^^^
  File "/usr/local/lib/python3.11/site-packages/django/template/base.py", line 196, in compile_nodelist
    return parser.parse()
           ^^^^^^^^^^^^^^
  File "/usr/local/lib/python3.11/site-packages/django/template/base.py", line 510, in parse
    raise self.error(token, e)
  File "/usr/local/lib/python3.11/site-packages/django/template/base.py", line 508, in parse
    compiled_result = compile_func(self, token)
                      ^^^^^^^^^^^^^^^^^^^^^^^^^
  File "/usr/local/lib/python3.11/site-packages/django/template/loader_tags.py", line 295, in do_extends
    nodelist = parser.parse()
               ^^^^^^^^^^^^^^
  File "/usr/local/lib/python3.11/site-packages/django/template/base.py", line 510, in parse
    raise self.error(token, e)
  File "/usr/local/lib/python3.11/site-packages/django/template/base.py", line 508, in parse
    compiled_result = compile_func(self, token)
                      ^^^^^^^^^^^^^^^^^^^^^^^^^
  File "/usr/local/lib/python3.11/site-packages/django/template/loader_tags.py", line 234, in do_block
    nodelist = parser.parse(("endblock",))
               ^^^^^^^^^^^^^^^^^^^^^^^^^^^
  File "/usr/local/lib/python3.11/site-packages/django/template/base.py", line 510, in parse
    raise self.error(token, e)
  File "/usr/local/lib/python3.11/site-packages/django/template/base.py", line 508, in parse
    compiled_result = compile_func(self, token)
                      ^^^^^^^^^^^^^^^^^^^^^^^^^
  File "/usr/local/lib/python3.11/site-packages/django/template/defaulttags.py", line 960, in do_if
    nodelist = parser.parse(("elif", "else", "endif"))
               ^^^^^^^^^^^^^^^^^^^^^^^^^^^^^^^^^^^^^^^
  File "/usr/local/lib/python3.11/site-packages/django/template/base.py", line 510, in parse
    raise self.error(token, e)
  File "/usr/local/lib/python3.11/site-packages/django/template/base.py", line 508, in parse
    compiled_result = compile_func(self, token)
                      ^^^^^^^^^^^^^^^^^^^^^^^^^
  File "/usr/local/lib/python3.11/site-packages/django/template/defaulttags.py", line 860, in do_for
    nodelist_loop = parser.parse(
                    ^^^^^^^^^^^^^
  File "/usr/local/lib/python3.11/site-packages/django/template/base.py", line 481, in parse
    raise self.error(token, e)
  File "/usr/local/lib/python3.11/site-packages/django/template/base.py", line 479, in parse
    filter_expression = self.compile_filter(token.contents)
                        ^^^^^^^^^^^^^^^^^^^^^^^^^^^^^^^^^^^
  File "/usr/local/lib/python3.11/site-packages/django/template/base.py", line 597, in compile_filter
    return FilterExpression(token, self)
           ^^^^^^^^^^^^^^^^^^^^^^^^^^^^^
  File "/usr/local/lib/python3.11/site-packages/django/template/base.py", line 698, in __init__
    raise TemplateSyntaxError(
django.template.exceptions.TemplateSyntaxError: Could not parse the remainder: '["action"]' from 'row.2["action"]'
Internal Server Error: /user/
Traceback (most recent call last):
  File "/usr/local/lib/python3.11/site-packages/django/core/handlers/exception.py", line 55, in inner
    response = get_response(request)
               ^^^^^^^^^^^^^^^^^^^^^
  File "/usr/local/lib/python3.11/site-packages/django/core/handlers/base.py", line 197, in _get_response
    response = wrapped_callback(request, *callback_args, **callback_kwargs)
               ^^^^^^^^^^^^^^^^^^^^^^^^^^^^^^^^^^^^^^^^^^^^^^^^^^^^^^^^^^^^
  File "/usr/src/app/myapp/views.py", line 82, in users
    return render(request, 'user_page.html', context)
           ^^^^^^^^^^^^^^^^^^^^^^^^^^^^^^^^^^^^^^^^^^
  File "/usr/local/lib/python3.11/site-packages/django/shortcuts.py", line 24, in render
    content = loader.render_to_string(template_name, context, request, using=using)
              ^^^^^^^^^^^^^^^^^^^^^^^^^^^^^^^^^^^^^^^^^^^^^^^^^^^^^^^^^^^^^^^^^^^^^
  File "/usr/local/lib/python3.11/site-packages/django/template/loader.py", line 61, in render_to_string
    template = get_template(template_name, using=using)
               ^^^^^^^^^^^^^^^^^^^^^^^^^^^^^^^^^^^^^^^^
  File "/usr/local/lib/python3.11/site-packages/django/template/loader.py", line 15, in get_template
    return engine.get_template(template_name)
           ^^^^^^^^^^^^^^^^^^^^^^^^^^^^^^^^^^
  File "/usr/local/lib/python3.11/site-packages/django/template/backends/django.py", line 33, in get_template
    return Template(self.engine.get_template(template_name), self)
                    ^^^^^^^^^^^^^^^^^^^^^^^^^^^^^^^^^^^^^^^
  File "/usr/local/lib/python3.11/site-packages/django/template/engine.py", line 175, in get_template
    template, origin = self.find_template(template_name)
                       ^^^^^^^^^^^^^^^^^^^^^^^^^^^^^^^^^
  File "/usr/local/lib/python3.11/site-packages/django/template/engine.py", line 157, in find_template
    template = loader.get_template(name, skip=skip)
               ^^^^^^^^^^^^^^^^^^^^^^^^^^^^^^^^^^^^
  File "/usr/local/lib/python3.11/site-packages/django/template/loaders/cached.py", line 57, in get_template
    template = super().get_template(template_name, skip)
               ^^^^^^^^^^^^^^^^^^^^^^^^^^^^^^^^^^^^^^^^^
  File "/usr/local/lib/python3.11/site-packages/django/template/loaders/base.py", line 28, in get_template
    return Template(
           ^^^^^^^^^
  File "/usr/local/lib/python3.11/site-packages/django/template/base.py", line 154, in __init__
    self.nodelist = self.compile_nodelist()
                    ^^^^^^^^^^^^^^^^^^^^^^^
  File "/usr/local/lib/python3.11/site-packages/django/template/base.py", line 196, in compile_nodelist
    return parser.parse()
           ^^^^^^^^^^^^^^
  File "/usr/local/lib/python3.11/site-packages/django/template/base.py", line 510, in parse
    raise self.error(token, e)
  File "/usr/local/lib/python3.11/site-packages/django/template/base.py", line 508, in parse
    compiled_result = compile_func(self, token)
                      ^^^^^^^^^^^^^^^^^^^^^^^^^
  File "/usr/local/lib/python3.11/site-packages/django/template/loader_tags.py", line 295, in do_extends
    nodelist = parser.parse()
               ^^^^^^^^^^^^^^
  File "/usr/local/lib/python3.11/site-packages/django/template/base.py", line 510, in parse
    raise self.error(token, e)
  File "/usr/local/lib/python3.11/site-packages/django/template/base.py", line 508, in parse
    compiled_result = compile_func(self, token)
                      ^^^^^^^^^^^^^^^^^^^^^^^^^
  File "/usr/local/lib/python3.11/site-packages/django/template/loader_tags.py", line 234, in do_block
    nodelist = parser.parse(("endblock",))
               ^^^^^^^^^^^^^^^^^^^^^^^^^^^
  File "/usr/local/lib/python3.11/site-packages/django/template/base.py", line 510, in parse
    raise self.error(token, e)
  File "/usr/local/lib/python3.11/site-packages/django/template/base.py", line 508, in parse
    compiled_result = compile_func(self, token)
                      ^^^^^^^^^^^^^^^^^^^^^^^^^
  File "/usr/local/lib/python3.11/site-packages/django/template/defaulttags.py", line 960, in do_if
    nodelist = parser.parse(("elif", "else", "endif"))
               ^^^^^^^^^^^^^^^^^^^^^^^^^^^^^^^^^^^^^^^
  File "/usr/local/lib/python3.11/site-packages/django/template/base.py", line 510, in parse
    raise self.error(token, e)
  File "/usr/local/lib/python3.11/site-packages/django/template/base.py", line 508, in parse
    compiled_result = compile_func(self, token)
                      ^^^^^^^^^^^^^^^^^^^^^^^^^
  File "/usr/local/lib/python3.11/site-packages/django/template/defaulttags.py", line 860, in do_for
    nodelist_loop = parser.parse(
                    ^^^^^^^^^^^^^
  File "/usr/local/lib/python3.11/site-packages/django/template/base.py", line 481, in parse
    raise self.error(token, e)
  File "/usr/local/lib/python3.11/site-packages/django/template/base.py", line 479, in parse
    filter_expression = self.compile_filter(token.contents)
                        ^^^^^^^^^^^^^^^^^^^^^^^^^^^^^^^^^^^
  File "/usr/local/lib/python3.11/site-packages/django/template/base.py", line 597, in compile_filter
    return FilterExpression(token, self)
           ^^^^^^^^^^^^^^^^^^^^^^^^^^^^^
  File "/usr/local/lib/python3.11/site-packages/django/template/base.py", line 698, in __init__
    raise TemplateSyntaxError(
django.template.exceptions.TemplateSyntaxError: Could not parse the remainder: '["action"]' from 'row.2.["action"]'
Internal Server Error: /user/
Traceback (most recent call last):
  File "/usr/local/lib/python3.11/site-packages/django/core/handlers/exception.py", line 55, in inner
    response = get_response(request)
               ^^^^^^^^^^^^^^^^^^^^^
  File "/usr/local/lib/python3.11/site-packages/django/core/handlers/base.py", line 197, in _get_response
    response = wrapped_callback(request, *callback_args, **callback_kwargs)
               ^^^^^^^^^^^^^^^^^^^^^^^^^^^^^^^^^^^^^^^^^^^^^^^^^^^^^^^^^^^^
  File "/usr/src/app/myapp/views.py", line 82, in users
    return render(request, 'user_page.html', context)
           ^^^^^^^^^^^^^^^^^^^^^^^^^^^^^^^^^^^^^^^^^^
  File "/usr/local/lib/python3.11/site-packages/django/shortcuts.py", line 24, in render
    content = loader.render_to_string(template_name, context, request, using=using)
              ^^^^^^^^^^^^^^^^^^^^^^^^^^^^^^^^^^^^^^^^^^^^^^^^^^^^^^^^^^^^^^^^^^^^^
  File "/usr/local/lib/python3.11/site-packages/django/template/loader.py", line 61, in render_to_string
    template = get_template(template_name, using=using)
               ^^^^^^^^^^^^^^^^^^^^^^^^^^^^^^^^^^^^^^^^
  File "/usr/local/lib/python3.11/site-packages/django/template/loader.py", line 15, in get_template
    return engine.get_template(template_name)
           ^^^^^^^^^^^^^^^^^^^^^^^^^^^^^^^^^^
  File "/usr/local/lib/python3.11/site-packages/django/template/backends/django.py", line 33, in get_template
    return Template(self.engine.get_template(template_name), self)
                    ^^^^^^^^^^^^^^^^^^^^^^^^^^^^^^^^^^^^^^^
  File "/usr/local/lib/python3.11/site-packages/django/template/engine.py", line 175, in get_template
    template, origin = self.find_template(template_name)
                       ^^^^^^^^^^^^^^^^^^^^^^^^^^^^^^^^^
  File "/usr/local/lib/python3.11/site-packages/django/template/engine.py", line 157, in find_template
    template = loader.get_template(name, skip=skip)
               ^^^^^^^^^^^^^^^^^^^^^^^^^^^^^^^^^^^^
  File "/usr/local/lib/python3.11/site-packages/django/template/loaders/cached.py", line 57, in get_template
    template = super().get_template(template_name, skip)
               ^^^^^^^^^^^^^^^^^^^^^^^^^^^^^^^^^^^^^^^^^
  File "/usr/local/lib/python3.11/site-packages/django/template/loaders/base.py", line 28, in get_template
    return Template(
           ^^^^^^^^^
  File "/usr/local/lib/python3.11/site-packages/django/template/base.py", line 154, in __init__
    self.nodelist = self.compile_nodelist()
                    ^^^^^^^^^^^^^^^^^^^^^^^
  File "/usr/local/lib/python3.11/site-packages/django/template/base.py", line 196, in compile_nodelist
    return parser.parse()
           ^^^^^^^^^^^^^^
  File "/usr/local/lib/python3.11/site-packages/django/template/base.py", line 510, in parse
    raise self.error(token, e)
  File "/usr/local/lib/python3.11/site-packages/django/template/base.py", line 508, in parse
    compiled_result = compile_func(self, token)
                      ^^^^^^^^^^^^^^^^^^^^^^^^^
  File "/usr/local/lib/python3.11/site-packages/django/template/loader_tags.py", line 295, in do_extends
    nodelist = parser.parse()
               ^^^^^^^^^^^^^^
  File "/usr/local/lib/python3.11/site-packages/django/template/base.py", line 510, in parse
    raise self.error(token, e)
  File "/usr/local/lib/python3.11/site-packages/django/template/base.py", line 508, in parse
    compiled_result = compile_func(self, token)
                      ^^^^^^^^^^^^^^^^^^^^^^^^^
  File "/usr/local/lib/python3.11/site-packages/django/template/loader_tags.py", line 234, in do_block
    nodelist = parser.parse(("endblock",))
               ^^^^^^^^^^^^^^^^^^^^^^^^^^^
  File "/usr/local/lib/python3.11/site-packages/django/template/base.py", line 510, in parse
    raise self.error(token, e)
  File "/usr/local/lib/python3.11/site-packages/django/template/base.py", line 508, in parse
    compiled_result = compile_func(self, token)
                      ^^^^^^^^^^^^^^^^^^^^^^^^^
  File "/usr/local/lib/python3.11/site-packages/django/template/defaulttags.py", line 960, in do_if
    nodelist = parser.parse(("elif", "else", "endif"))
               ^^^^^^^^^^^^^^^^^^^^^^^^^^^^^^^^^^^^^^^
  File "/usr/local/lib/python3.11/site-packages/django/template/base.py", line 510, in parse
    raise self.error(token, e)
  File "/usr/local/lib/python3.11/site-packages/django/template/base.py", line 508, in parse
    compiled_result = compile_func(self, token)
                      ^^^^^^^^^^^^^^^^^^^^^^^^^
  File "/usr/local/lib/python3.11/site-packages/django/template/defaulttags.py", line 860, in do_for
    nodelist_loop = parser.parse(
                    ^^^^^^^^^^^^^
  File "/usr/local/lib/python3.11/site-packages/django/template/base.py", line 481, in parse
    raise self.error(token, e)
  File "/usr/local/lib/python3.11/site-packages/django/template/base.py", line 479, in parse
    filter_expression = self.compile_filter(token.contents)
                        ^^^^^^^^^^^^^^^^^^^^^^^^^^^^^^^^^^^
  File "/usr/local/lib/python3.11/site-packages/django/template/base.py", line 597, in compile_filter
    return FilterExpression(token, self)
           ^^^^^^^^^^^^^^^^^^^^^^^^^^^^^
  File "/usr/local/lib/python3.11/site-packages/django/template/base.py", line 698, in __init__
    raise TemplateSyntaxError(
django.template.exceptions.TemplateSyntaxError: Could not parse the remainder: '["action"]' from 'row.2.["action"]'
/usr/src/app/myapp/views.py changed, reloading.
Watching for file changes with StatReloader
Internal Server Error: /user/
Traceback (most recent call last):
  File "/usr/local/lib/python3.11/site-packages/django/core/handlers/exception.py", line 55, in inner
    response = get_response(request)
               ^^^^^^^^^^^^^^^^^^^^^
  File "/usr/local/lib/python3.11/site-packages/django/core/handlers/base.py", line 197, in _get_response
    response = wrapped_callback(request, *callback_args, **callback_kwargs)
               ^^^^^^^^^^^^^^^^^^^^^^^^^^^^^^^^^^^^^^^^^^^^^^^^^^^^^^^^^^^^
  File "/usr/src/app/myapp/views.py", line 82, in users
    data = admin_table(request)
           ^^^^^^^^^^^^^^^^^^^^
  File "/usr/src/app/myapp/views.py", line 57, in admin_table
    log = json.loads(row[2])
          ^^^^
NameError: name 'json' is not defined
/usr/src/app/myapp/views.py changed, reloading.
Watching for file changes with StatReloader
Internal Server Error: /user/
Traceback (most recent call last):
  File "/usr/local/lib/python3.11/site-packages/django/core/handlers/exception.py", line 55, in inner
    response = get_response(request)
               ^^^^^^^^^^^^^^^^^^^^^
  File "/usr/local/lib/python3.11/site-packages/django/core/handlers/base.py", line 197, in _get_response
    response = wrapped_callback(request, *callback_args, **callback_kwargs)
               ^^^^^^^^^^^^^^^^^^^^^^^^^^^^^^^^^^^^^^^^^^^^^^^^^^^^^^^^^^^^
  File "/usr/src/app/myapp/views.py", line 85, in users
    context = {'data': data['data']}
                       ~~~~^^^^^^^^
  File "/usr/local/lib/python3.11/site-packages/django/http/response.py", line 199, in __getitem__
    return self.headers[header]
           ~~~~~~~~~~~~^^^^^^^^
  File "/usr/local/lib/python3.11/site-packages/django/utils/datastructures.py", line 308, in __getitem__
    return self._store[key.lower()][1]
           ~~~~~~~~~~~^^^^^^^^^^^^^
KeyError: 'data'
/usr/src/app/myapp/views.py changed, reloading.
Watching for file changes with StatReloader
Internal Server Error: /user/
Traceback (most recent call last):
  File "/usr/local/lib/python3.11/site-packages/django/core/handlers/exception.py", line 55, in inner
    response = get_response(request)
               ^^^^^^^^^^^^^^^^^^^^^
  File "/usr/local/lib/python3.11/site-packages/django/core/handlers/base.py", line 197, in _get_response
    response = wrapped_callback(request, *callback_args, **callback_kwargs)
               ^^^^^^^^^^^^^^^^^^^^^^^^^^^^^^^^^^^^^^^^^^^^^^^^^^^^^^^^^^^^
  File "/usr/src/app/myapp/views.py", line 86, in users
    context = {'data': data['data']}
                       ~~~~^^^^^^^^
  File "/usr/local/lib/python3.11/site-packages/django/http/response.py", line 199, in __getitem__
    return self.headers[header]
           ~~~~~~~~~~~~^^^^^^^^
  File "/usr/local/lib/python3.11/site-packages/django/utils/datastructures.py", line 308, in __getitem__
    return self._store[key.lower()][1]
           ~~~~~~~~~~~^^^^^^^^^^^^^
KeyError: 'data'
/usr/src/app/myapp/views.py changed, reloading.
Watching for file changes with StatReloader
Internal Server Error: /user/
Traceback (most recent call last):
  File "/usr/local/lib/python3.11/site-packages/django/core/handlers/exception.py", line 55, in inner
    response = get_response(request)
               ^^^^^^^^^^^^^^^^^^^^^
  File "/usr/local/lib/python3.11/site-packages/django/core/handlers/base.py", line 197, in _get_response
    response = wrapped_callback(request, *callback_args, **callback_kwargs)
               ^^^^^^^^^^^^^^^^^^^^^^^^^^^^^^^^^^^^^^^^^^^^^^^^^^^^^^^^^^^^
  File "/usr/src/app/myapp/views.py", line 84, in users
    print(data['data'])
          ~~~~^^^^^^^^
  File "/usr/local/lib/python3.11/site-packages/django/http/response.py", line 199, in __getitem__
    return self.headers[header]
           ~~~~~~~~~~~~^^^^^^^^
  File "/usr/local/lib/python3.11/site-packages/django/utils/datastructures.py", line 308, in __getitem__
    return self._store[key.lower()][1]
           ~~~~~~~~~~~^^^^^^^^^^^^^
KeyError: 'data'
/usr/src/app/myapp/views.py changed, reloading.
Watching for file changes with StatReloader
Internal Server Error: /user/
Traceback (most recent call last):
  File "/usr/local/lib/python3.11/site-packages/django/core/handlers/exception.py", line 55, in inner
    response = get_response(request)
               ^^^^^^^^^^^^^^^^^^^^^
  File "/usr/local/lib/python3.11/site-packages/django/core/handlers/base.py", line 197, in _get_response
    response = wrapped_callback(request, *callback_args, **callback_kwargs)
               ^^^^^^^^^^^^^^^^^^^^^^^^^^^^^^^^^^^^^^^^^^^^^^^^^^^^^^^^^^^^
  File "/usr/src/app/myapp/views.py", line 84, in users
    print(data['data'])
          ~~~~^^^^^^^^
  File "/usr/local/lib/python3.11/site-packages/django/http/response.py", line 199, in __getitem__
    return self.headers[header]
           ~~~~~~~~~~~~^^^^^^^^
  File "/usr/local/lib/python3.11/site-packages/django/utils/datastructures.py", line 308, in __getitem__
    return self._store[key.lower()][1]
           ~~~~~~~~~~~^^^^^^^^^^^^^
KeyError: 'data'
Internal Server Error: /user/
Traceback (most recent call last):
  File "/usr/local/lib/python3.11/site-packages/django/core/handlers/exception.py", line 55, in inner
    response = get_response(request)
               ^^^^^^^^^^^^^^^^^^^^^
  File "/usr/local/lib/python3.11/site-packages/django/core/handlers/base.py", line 197, in _get_response
    response = wrapped_callback(request, *callback_args, **callback_kwargs)
               ^^^^^^^^^^^^^^^^^^^^^^^^^^^^^^^^^^^^^^^^^^^^^^^^^^^^^^^^^^^^
  File "/usr/src/app/myapp/views.py", line 84, in users
    print(data['data'])
          ~~~~^^^^^^^^
  File "/usr/local/lib/python3.11/site-packages/django/http/response.py", line 199, in __getitem__
    return self.headers[header]
           ~~~~~~~~~~~~^^^^^^^^
  File "/usr/local/lib/python3.11/site-packages/django/utils/datastructures.py", line 308, in __getitem__
    return self._store[key.lower()][1]
           ~~~~~~~~~~~^^^^^^^^^^^^^
KeyError: 'data'
Internal Server Error: /user/
Traceback (most recent call last):
  File "/usr/local/lib/python3.11/site-packages/django/core/handlers/exception.py", line 55, in inner
    response = get_response(request)
               ^^^^^^^^^^^^^^^^^^^^^
  File "/usr/local/lib/python3.11/site-packages/django/core/handlers/base.py", line 197, in _get_response
    response = wrapped_callback(request, *callback_args, **callback_kwargs)
               ^^^^^^^^^^^^^^^^^^^^^^^^^^^^^^^^^^^^^^^^^^^^^^^^^^^^^^^^^^^^
  File "/usr/src/app/myapp/views.py", line 84, in users
    print(data['data'])
          ~~~~^^^^^^^^
  File "/usr/local/lib/python3.11/site-packages/django/http/response.py", line 199, in __getitem__
    return self.headers[header]
           ~~~~~~~~~~~~^^^^^^^^
  File "/usr/local/lib/python3.11/site-packages/django/utils/datastructures.py", line 308, in __getitem__
    return self._store[key.lower()][1]
           ~~~~~~~~~~~^^^^^^^^^^^^^
KeyError: 'data'
Internal Server Error: /user/
Traceback (most recent call last):
  File "/usr/local/lib/python3.11/site-packages/django/core/handlers/exception.py", line 55, in inner
    response = get_response(request)
               ^^^^^^^^^^^^^^^^^^^^^
  File "/usr/local/lib/python3.11/site-packages/django/core/handlers/base.py", line 197, in _get_response
    response = wrapped_callback(request, *callback_args, **callback_kwargs)
               ^^^^^^^^^^^^^^^^^^^^^^^^^^^^^^^^^^^^^^^^^^^^^^^^^^^^^^^^^^^^
  File "/usr/src/app/myapp/views.py", line 84, in users
    print(data['data'])
          ~~~~^^^^^^^^
  File "/usr/local/lib/python3.11/site-packages/django/http/response.py", line 199, in __getitem__
    return self.headers[header]
           ~~~~~~~~~~~~^^^^^^^^
  File "/usr/local/lib/python3.11/site-packages/django/utils/datastructures.py", line 308, in __getitem__
    return self._store[key.lower()][1]
           ~~~~~~~~~~~^^^^^^^^^^^^^
KeyError: 'data'
/usr/src/app/myapp/views.py changed, reloading.
Watching for file changes with StatReloader
/usr/src/app/myapp/views.py changed, reloading.
Watching for file changes with StatReloader
/usr/src/app/myapp/views.py changed, reloading.
Watching for file changes with StatReloader
/usr/src/app/myapp/views.py changed, reloading.
Watching for file changes with StatReloader
Internal Server Error: /user/
Traceback (most recent call last):
  File "/usr/local/lib/python3.11/site-packages/django/core/handlers/exception.py", line 55, in inner
    response = get_response(request)
               ^^^^^^^^^^^^^^^^^^^^^
  File "/usr/local/lib/python3.11/site-packages/django/core/handlers/base.py", line 197, in _get_response
    response = wrapped_callback(request, *callback_args, **callback_kwargs)
               ^^^^^^^^^^^^^^^^^^^^^^^^^^^^^^^^^^^^^^^^^^^^^^^^^^^^^^^^^^^^
  File "/usr/src/app/myapp/views.py", line 87, in users
    data = admin_table(request)
           ^^^^^^^^^^^^^^^^^^^^
  File "/usr/src/app/myapp/views.py", line 61, in admin_table
    dt = datetime.fromisoformat(row[0])
         ^^^^^^^^^^^^^^^^^^^^^^^^^^^^^^
TypeError: fromisoformat: argument must be str
/usr/src/app/myapp/views.py changed, reloading.
Watching for file changes with StatReloader
Internal Server Error: /user/
Traceback (most recent call last):
  File "/usr/local/lib/python3.11/site-packages/django/core/handlers/exception.py", line 55, in inner
    response = get_response(request)
               ^^^^^^^^^^^^^^^^^^^^^
  File "/usr/local/lib/python3.11/site-packages/django/core/handlers/base.py", line 197, in _get_response
    response = wrapped_callback(request, *callback_args, **callback_kwargs)
               ^^^^^^^^^^^^^^^^^^^^^^^^^^^^^^^^^^^^^^^^^^^^^^^^^^^^^^^^^^^^
  File "/usr/src/app/myapp/views.py", line 87, in users
    data = admin_table(request)
           ^^^^^^^^^^^^^^^^^^^^
  File "/usr/src/app/myapp/views.py", line 61, in admin_table
    dt = datetime.fromisoformat(string(row[0]))
                                ^^^^^^
NameError: name 'string' is not defined
Internal Server Error: /user/
Traceback (most recent call last):
  File "/usr/local/lib/python3.11/site-packages/django/core/handlers/exception.py", line 55, in inner
    response = get_response(request)
               ^^^^^^^^^^^^^^^^^^^^^
  File "/usr/local/lib/python3.11/site-packages/django/core/handlers/base.py", line 197, in _get_response
    response = wrapped_callback(request, *callback_args, **callback_kwargs)
               ^^^^^^^^^^^^^^^^^^^^^^^^^^^^^^^^^^^^^^^^^^^^^^^^^^^^^^^^^^^^
  File "/usr/src/app/myapp/views.py", line 87, in users
    data = admin_table(request)
           ^^^^^^^^^^^^^^^^^^^^
  File "/usr/src/app/myapp/views.py", line 61, in admin_table
    dt = datetime.fromisoformat(string(row[0]))
                                ^^^^^^
NameError: name 'string' is not defined
Internal Server Error: /user/
Traceback (most recent call last):
  File "/usr/local/lib/python3.11/site-packages/django/core/handlers/exception.py", line 55, in inner
    response = get_response(request)
               ^^^^^^^^^^^^^^^^^^^^^
  File "/usr/local/lib/python3.11/site-packages/django/core/handlers/base.py", line 197, in _get_response
    response = wrapped_callback(request, *callback_args, **callback_kwargs)
               ^^^^^^^^^^^^^^^^^^^^^^^^^^^^^^^^^^^^^^^^^^^^^^^^^^^^^^^^^^^^
  File "/usr/src/app/myapp/views.py", line 87, in users
    data = admin_table(request)
           ^^^^^^^^^^^^^^^^^^^^
  File "/usr/src/app/myapp/views.py", line 61, in admin_table
    dt = datetime.fromisoformat(string(row[0]))
                                ^^^^^^
NameError: name 'string' is not defined
Internal Server Error: /user/
Traceback (most recent call last):
  File "/usr/local/lib/python3.11/site-packages/django/core/handlers/exception.py", line 55, in inner
    response = get_response(request)
               ^^^^^^^^^^^^^^^^^^^^^
  File "/usr/local/lib/python3.11/site-packages/django/core/handlers/base.py", line 197, in _get_response
    response = wrapped_callback(request, *callback_args, **callback_kwargs)
               ^^^^^^^^^^^^^^^^^^^^^^^^^^^^^^^^^^^^^^^^^^^^^^^^^^^^^^^^^^^^
  File "/usr/src/app/myapp/views.py", line 87, in users
    data = admin_table(request)
           ^^^^^^^^^^^^^^^^^^^^
  File "/usr/src/app/myapp/views.py", line 61, in admin_table
    dt = datetime.fromisoformat(string(row[0]))
                                ^^^^^^
NameError: name 'string' is not defined
Internal Server Error: /user/
Traceback (most recent call last):
  File "/usr/local/lib/python3.11/site-packages/django/core/handlers/exception.py", line 55, in inner
    response = get_response(request)
               ^^^^^^^^^^^^^^^^^^^^^
  File "/usr/local/lib/python3.11/site-packages/django/core/handlers/base.py", line 197, in _get_response
    response = wrapped_callback(request, *callback_args, **callback_kwargs)
               ^^^^^^^^^^^^^^^^^^^^^^^^^^^^^^^^^^^^^^^^^^^^^^^^^^^^^^^^^^^^
  File "/usr/src/app/myapp/views.py", line 87, in users
    data = admin_table(request)
           ^^^^^^^^^^^^^^^^^^^^
  File "/usr/src/app/myapp/views.py", line 61, in admin_table
    dt = datetime.fromisoformat(string(row[0]))
                                ^^^^^^
NameError: name 'string' is not defined
Internal Server Error: /user/
Traceback (most recent call last):
  File "/usr/local/lib/python3.11/site-packages/django/core/handlers/exception.py", line 55, in inner
    response = get_response(request)
               ^^^^^^^^^^^^^^^^^^^^^
  File "/usr/local/lib/python3.11/site-packages/django/core/handlers/base.py", line 197, in _get_response
    response = wrapped_callback(request, *callback_args, **callback_kwargs)
               ^^^^^^^^^^^^^^^^^^^^^^^^^^^^^^^^^^^^^^^^^^^^^^^^^^^^^^^^^^^^
  File "/usr/src/app/myapp/views.py", line 87, in users
    data = admin_table(request)
           ^^^^^^^^^^^^^^^^^^^^
  File "/usr/src/app/myapp/views.py", line 61, in admin_table
    dt = datetime.fromisoformat(string(row[0]))
                                ^^^^^^
NameError: name 'string' is not defined
/usr/src/app/myapp/views.py changed, reloading.
Watching for file changes with StatReloader
/usr/src/app/myapp/views.py changed, reloading.
Watching for file changes with StatReloader
/usr/src/app/myapp/views.py changed, reloading.
Watching for file changes with StatReloader
/usr/src/app/myapp/views.py changed, reloading.
Watching for file changes with StatReloader
/usr/src/app/myapp/views.py changed, reloading.
Watching for file changes with StatReloader
/usr/src/app/myapp/views.py changed, reloading.
Watching for file changes with StatReloader
/usr/src/app/myapp/views.py changed, reloading.
Watching for file changes with StatReloader
/usr/src/app/myapp/views.py changed, reloading.
Watching for file changes with StatReloader
/usr/src/app/myapp/models.py changed, reloading.
Watching for file changes with StatReloader
/usr/src/app/myapp/models.py changed, reloading.
Watching for file changes with StatReloader
/usr/src/app/myapp/views.py changed, reloading.
Watching for file changes with StatReloader
Watching for file changes with StatReloader
Watching for file changes with StatReloader
Not Found: /favicon.ico
Not Found: /favicon.ico
Not Found: /favicon.ico
Not Found: /favicon.ico
Not Found: /favicon.ico
Internal Server Error: /user/
Traceback (most recent call last):
  File "/usr/local/lib/python3.11/site-packages/django/template/base.py", line 502, in parse
    compile_func = self.tags[command]
                   ~~~~~~~~~^^^^^^^^^
KeyError: 'endblock'

During handling of the above exception, another exception occurred:

Traceback (most recent call last):
  File "/usr/local/lib/python3.11/site-packages/django/core/handlers/exception.py", line 55, in inner
    response = get_response(request)
               ^^^^^^^^^^^^^^^^^^^^^
  File "/usr/local/lib/python3.11/site-packages/django/core/handlers/base.py", line 197, in _get_response
    response = wrapped_callback(request, *callback_args, **callback_kwargs)
               ^^^^^^^^^^^^^^^^^^^^^^^^^^^^^^^^^^^^^^^^^^^^^^^^^^^^^^^^^^^^
  File "/usr/src/app/myapp/views.py", line 187, in users
    return render(request, 'user_page.html', context)
           ^^^^^^^^^^^^^^^^^^^^^^^^^^^^^^^^^^^^^^^^^^
  File "/usr/local/lib/python3.11/site-packages/django/shortcuts.py", line 24, in render
    content = loader.render_to_string(template_name, context, request, using=using)
              ^^^^^^^^^^^^^^^^^^^^^^^^^^^^^^^^^^^^^^^^^^^^^^^^^^^^^^^^^^^^^^^^^^^^^
  File "/usr/local/lib/python3.11/site-packages/django/template/loader.py", line 61, in render_to_string
    template = get_template(template_name, using=using)
               ^^^^^^^^^^^^^^^^^^^^^^^^^^^^^^^^^^^^^^^^
  File "/usr/local/lib/python3.11/site-packages/django/template/loader.py", line 15, in get_template
    return engine.get_template(template_name)
           ^^^^^^^^^^^^^^^^^^^^^^^^^^^^^^^^^^
  File "/usr/local/lib/python3.11/site-packages/django/template/backends/django.py", line 33, in get_template
    return Template(self.engine.get_template(template_name), self)
                    ^^^^^^^^^^^^^^^^^^^^^^^^^^^^^^^^^^^^^^^
  File "/usr/local/lib/python3.11/site-packages/django/template/engine.py", line 175, in get_template
    template, origin = self.find_template(template_name)
                       ^^^^^^^^^^^^^^^^^^^^^^^^^^^^^^^^^
  File "/usr/local/lib/python3.11/site-packages/django/template/engine.py", line 157, in find_template
    template = loader.get_template(name, skip=skip)
               ^^^^^^^^^^^^^^^^^^^^^^^^^^^^^^^^^^^^
  File "/usr/local/lib/python3.11/site-packages/django/template/loaders/cached.py", line 57, in get_template
    template = super().get_template(template_name, skip)
               ^^^^^^^^^^^^^^^^^^^^^^^^^^^^^^^^^^^^^^^^^
  File "/usr/local/lib/python3.11/site-packages/django/template/loaders/base.py", line 28, in get_template
    return Template(
           ^^^^^^^^^
  File "/usr/local/lib/python3.11/site-packages/django/template/base.py", line 154, in __init__
    self.nodelist = self.compile_nodelist()
                    ^^^^^^^^^^^^^^^^^^^^^^^
  File "/usr/local/lib/python3.11/site-packages/django/template/base.py", line 196, in compile_nodelist
    return parser.parse()
           ^^^^^^^^^^^^^^
  File "/usr/local/lib/python3.11/site-packages/django/template/base.py", line 510, in parse
    raise self.error(token, e)
  File "/usr/local/lib/python3.11/site-packages/django/template/base.py", line 508, in parse
    compiled_result = compile_func(self, token)
                      ^^^^^^^^^^^^^^^^^^^^^^^^^
  File "/usr/local/lib/python3.11/site-packages/django/template/loader_tags.py", line 295, in do_extends
    nodelist = parser.parse()
               ^^^^^^^^^^^^^^
  File "/usr/local/lib/python3.11/site-packages/django/template/base.py", line 510, in parse
    raise self.error(token, e)
  File "/usr/local/lib/python3.11/site-packages/django/template/base.py", line 508, in parse
    compiled_result = compile_func(self, token)
                      ^^^^^^^^^^^^^^^^^^^^^^^^^
  File "/usr/local/lib/python3.11/site-packages/django/template/loader_tags.py", line 234, in do_block
    nodelist = parser.parse(("endblock",))
               ^^^^^^^^^^^^^^^^^^^^^^^^^^^
  File "/usr/local/lib/python3.11/site-packages/django/template/base.py", line 510, in parse
    raise self.error(token, e)
  File "/usr/local/lib/python3.11/site-packages/django/template/base.py", line 508, in parse
    compiled_result = compile_func(self, token)
                      ^^^^^^^^^^^^^^^^^^^^^^^^^
  File "/usr/local/lib/python3.11/site-packages/django/template/defaulttags.py", line 960, in do_if
    nodelist = parser.parse(("elif", "else", "endif"))
               ^^^^^^^^^^^^^^^^^^^^^^^^^^^^^^^^^^^^^^^
  File "/usr/local/lib/python3.11/site-packages/django/template/base.py", line 504, in parse
    self.invalid_block_tag(token, command, parse_until)
  File "/usr/local/lib/python3.11/site-packages/django/template/base.py", line 555, in invalid_block_tag
    raise self.error(
django.template.exceptions.TemplateSyntaxError: Invalid block tag on line 262: 'endblock', expected 'elif', 'else' or 'endif'. Did you forget to register or load this tag?
Watching for file changes with StatReloader
Not Found: /favicon.ico
Watching for file changes with StatReloader
